Workbook

Sheet Dashboard
A1: 📑 Tesouraria — Dashboard Financeiro
A2: Filtrar Mês: | B2: Ano Inteiro | D2: Mês Atual: | E2: =ÍNDICE(Configurações!$B$35:$B$46;MÊS(HOJE()))
L3: Jan | M3: ='Resumo Financeiro'!E3 | N3: ='Resumo Financeiro'!F3 | O3: =Configurações!$B$10+SOMA($M$3:M3)-SOMA($N$3:N3) | S3: Água | T3: =SOMASE(Gastos!$B$3:$B$502;S3;Gastos!$F$3:$F$502)
A4: 💰 Total Entradas | D4: 🟢 SALDO ATUAL | I4: 💸 Total Gastos | L4: Fev | M4: ='Resumo Financeiro'!E4 | N4: ='Resumo Financeiro'!F4 | O4: =Configurações!$B$10+SOMA($M$3:M4)-SOMA($N$3:N4) | S4: Energia | T4: =SOMASE(Gastos!$B$3:$B$502;S4;Gastos!$F$3:$F$502)
A5: ='Resumo Financeiro'!E15 | I5: ='Resumo Financeiro'!F15 | L5: Mar | M5: ='Resumo Financeiro'!E5 | N5: ='Resumo Financeiro'!F5 | O5: =Configurações!$B$10+SOMA($M$3:M5)-SOMA($N$3:N5) | S5: Limpeza | T5: =SOMASE(Gastos!$B$3:$B$502;S5;Gastos!$F$3:$F$502)
D6: =Configurações!$B$10+SOMA('Resumo Financeiro'!E3:E14)-SOMA('Resumo Financeiro'!F3:F14) | L6: Abr | M6: ='Resumo Financeiro'!E6 | N6: ='Resumo Financeiro'!F6 | O6: =Configurações!$B$10+SOMA($M$3:M6)-SOMA($N$3:N6) | S6: Material Litúrgico | T6: =SOMASE(Gastos!$B$3:$B$502;S6;Gastos!$F$3:$F$502)
L7: Mai | M7: ='Resumo Financeiro'!E7 | N7: ='Resumo Financeiro'!F7 | O7: =Configurações!$B$10+SOMA($M$3:M7)-SOMA($N$3:N7) | S7: Hóstias | T7: =SOMASE(Gastos!$B$3:$B$502;S7;Gastos!$F$3:$F$502)
L8: Jun | M8: ='Resumo Financeiro'!E8 | N8: ='Resumo Financeiro'!F8 | O8: =Configurações!$B$10+SOMA($M$3:M8)-SOMA($N$3:N8) | S8: Vinho | T8: =SOMASE(Gastos!$B$3:$B$502;S8;Gastos!$F$3:$F$502)
A9: 📈 Resultado Ano | I9: 📅 Entradas Mês | L9: Jul | M9: ='Resumo Financeiro'!E9 | N9: ='Resumo Financeiro'!F9 | O9: =Configurações!$B$10+SOMA($M$3:M9)-SOMA($N$3:N9) | S9: Flores | T9: =SOMASE(Gastos!$B$3:$B$502;S9;Gastos!$F$3:$F$502)
A10: ='Resumo Financeiro'!G15 | I10: =ÍNDICE('Resumo Financeiro'!E3:E14;MÊS(HOJE())) | L10: Ago | M10: ='Resumo Financeiro'!E10 | N10: ='Resumo Financeiro'!F10 | O10: =Configurações!$B$10+SOMA($M$3:M10)-SOMA($N$3:N10) | S10: Som | T10: =SOMASE(Gastos!$B$3:$B$502;S10;Gastos!$F$3:$F$502)
L11: Set | M11: ='Resumo Financeiro'!E11 | N11: ='Resumo Financeiro'!F11 | O11: =Configurações!$B$10+SOMA($M$3:M11)-SOMA($N$3:N11) | S11: Manutenção | T11: =SOMASE(Gastos!$B$3:$B$502;S11;Gastos!$F$3:$F$502)
L12: Out | M12: ='Resumo Financeiro'!E12 | N12: ='Resumo Financeiro'!F12 | O12: =Configurações!$B$10+SOMA($M$3:M12)-SOMA($N$3:N12) | S12: Obras | T12: =SOMASE(Gastos!$B$3:$B$502;S12;Gastos!$F$3:$F$502)
L13: Nov | M13: ='Resumo Financeiro'!E13 | N13: ='Resumo Financeiro'!F13 | O13: =Configurações!$B$10+SOMA($M$3:M13)-SOMA($N$3:N13) | S13: Secretaria | T13: =SOMASE(Gastos!$B$3:$B$502;S13;Gastos!$F$3:$F$502)
A14: 📅 Gastos Mês | I14: 🎯 Meta Mês (%) | L14: Dez | M14: ='Resumo Financeiro'!E14 | N14: ='Resumo Financeiro'!F14 | O14: =Configurações!$B$10+SOMA($M$3:M14)-SOMA($N$3:N14) | S14: Eventos | T14: =SOMASE(Gastos!$B$3:$B$502;S14;Gastos!$F$3:$F$502)
A15: =ÍNDICE('Resumo Financeiro'!F3:F14;MÊS(HOJE())) | I15: =ÍNDICE('Resumo Financeiro'!I3:I14;MÊS(HOJE())) | S15: Alimentação | T15: =SOMASE(Gastos!$B$3:$B$502;S15;Gastos!$F$3:$F$502)
A16: ⚠️ ALERTAS INTELIGENTES | L16: Dízimos | M16: ='Resumo Financeiro'!B15 | S16: Transporte | T16: =SOMASE(Gastos!$B$3:$B$502;S16;Gastos!$F$3:$F$502)
A17: =SE(ÍNDICE('Resumo Financeiro'!F3:F14;MÊS(HOJE()))>ÍNDICE('Resumo Financeiro'!E3:E14;MÊS(HOJE()));"🔴 Gastos maiores que entradas do mês";"🟢 Entradas ≥ gastos do mês") | L17: Doações | M17: ='Resumo Financeiro'!C15 | S17: Outros | T17: =SOMASE(Gastos!$B$3:$B$502;S17;Gastos!$F$3:$F$502)
A18: =SE(D6<0;"🔴 Saldo negativo — atenção!";"🟢 Saldo positivo") | L18: Missas | M18: ='Resumo Financeiro'!D15
A19: =SE(ÍNDICE('Resumo Financeiro'!I3:I14;MÊS(HOJE()))>=1;"🟢 Meta mensal de arrecadação atingida!";"🟡 Meta mensal ainda não atingida")
A20: ="🟡 Verifique categorias acima do limite na aba Gastos (formatação condicional)"
A22: 🏦 CONCILIAÇÃO BANCÁRIA
A23: Total Conciliado (✅) | C23: =SOMASE('Conciliação Bancária'!F3:F502;"✅";'Conciliação Bancária'!C3:C502)
A24: Total Pendente | C24: =SOMA('Conciliação Bancária'!C3:C502)-C23
A25: Diferenças Encontradas | C25: =SOMA('Conciliação Bancária'!E3:E502)

Sheet Cadastro Dizimistas
A1: 👥 Cadastro de Dizimistas
A2: Código | B2: Nome | C2: Telefone | D2: Endereço | E2: Aniversário | F2: Observações
A3: =SE(B3="";"";LIN()-2)
A4: =SE(B4="";"";LIN()-2)
A5: =SE(B5="";"";LIN()-2)
A6: =SE(B6="";"";LIN()-2)
A7: =SE(B7="";"";LIN()-2)
A8: =SE(B8="";"";LIN()-2)
A9: =SE(B9="";"";LIN()-2)
A10: =SE(B10="";"";LIN()-2)
A11: =SE(B11="";"";LIN()-2)
A12: =SE(B12="";"";LIN()-2)
A13: =SE(B13="";"";LIN()-2)
A14: =SE(B14="";"";LIN()-2)
... A502: =SE(B502="";"";LIN()-2)

Sheet Pesquisa Dizimista
A1: 🔎 Pesquisa Rápida de Dizimista
A3: Nome do Dizimista:
A4: Telefone: | B4: =SEERRO(PROCV(B3;'Cadastro Dizimistas'!$B$3:$C$502;2;FALSO);"")
A5: Endereço: | B5: =SEERRO(PROCV(B3;'Cadastro Dizimistas'!$B$3:$D$502;3;FALSO);"")
A7: Data | B7: Nome | C7: Valor | D7: Forma Pagamento | E7: Conta | F7: Observação
A8: =SE(B3="";"";FILTRAR('Dízimos Mensais'!A3:G502;'Dízimos Mensais'!B3:B502=B3))
A9: ℹ️ Requer Excel 365 (função FILTRAR). Use o filtro na aba Dízimos em versões anteriores.

Sheet Dízimos Mensais
A1: 💰 Dízimos Mensais
A2: Data | B2: Nome | C2: Telefone | D2: Mês | E2: Valor | F2: Forma de Pagamento | G2: Conta | H2: Observação
C3: =SE(B3="";"";SEERRO(PROCV(B3;'Cadastro Dizimistas'!$B$3:$C$502;2;FALSO);"")) | D3: =SE(A3="";"";ÍNDICE(Configurações!$B$35:$B$46;MÊS(A3)))
C4: =SE(B4="";"";SEERRO(PROCV(B4;'Cadastro Dizimistas'!$B$3:$C$502;2;FALSO);"")) | D4: =SE(A4="";"";ÍNDICE(Configurações!$B$35:$B$46;MÊS(A4)))
C5: =SE(B5="";"";SEERRO(PROCV(B5;'Cadastro Dizimistas'!$B$3:$C$502;2;FALSO);"")) | D5: =SE(A5="";"";ÍNDICE(Configurações!$B$35:$B$46;MÊS(A5)))
C6: =SE(B6="";"";SEERRO(PROCV(B6;'Cadastro Dizimistas'!$B$3:$C$502;2;FALSO);"")) | D6: =SE(A6="";"";ÍNDICE(Configurações!$B$35:$B$46;MÊS(A6)))
C7: =SE(B7="";"";SEERRO(PROCV(B7;'Cadastro Dizimistas'!$B$3:$C$502;2;FALSO);"")) | D7: =SE(A7="";"";ÍNDICE(Configurações!$B$35:$B$46;MÊS(A7)))
C8: =SE(B8="";"";SEERRO(PROCV(B8;'Cadastro Dizimistas'!$B$3:$C$502;2;FALSO);"")) | D8: =SE(A8="";"";ÍNDICE(Configurações!$B$35:$B$46;MÊS(A8)))
C9: =SE(B9="";"";SEERRO(PROCV(B9;'Cadastro Dizimistas'!$B$3:$C$502;2;FALSO);"")) | D9: =SE(A9="";"";ÍNDICE(Configurações!$B$35:$B$46;MÊS(A9)))
C10: =SE(B10="";"";SEERRO(PROCV(B10;'Cadastro Dizimistas'!$B$3:$C$502;2;FALSO);"")) | D10: =SE(A10="";"";ÍNDICE(Configurações!$B$35:$B$46;MÊS(A10)))
C11: =SE(B11="";"";SEERRO(PROCV(B11;'Cadastro Dizimistas'!$B$3:$C$502;2;FALSO);"")) | D11: =SE(A11="";"";ÍNDICE(Configurações!$B$35:$B$46;MÊS(A11)))
C12: =SE(B12="";"";SEERRO(PROCV(B12;'Cadastro Dizimistas'!$B$3:$C$502;2;FALSO);"")) | D12: =SE(A12="";"";ÍNDICE(Configurações!$B$35:$B$46;MÊS(A12)))
C13: =SE(B13="";"";SEERRO(PROCV(B13;'Cadastro Dizimistas'!$B$3:$C$502;2;FALSO);"")) | D13: =SE(A13="";"";ÍNDICE(Configurações!$B$35:$B$46;MÊS(A13)))
C14: =SE(B14="";"";SEERRO(PROCV(B14;'Cadastro Dizimistas'!$B$3:$C$502;2;FALSO);"")) | D14: =SE(A14="";"";ÍNDICE(Configurações!$B$35:$B$46;MÊS(A14)))
... C502: =SE(B502="";"";SEERRO(PROCV(B502;'Cadastro Dizimistas'!$B$3:$C$502;2;FALSO);"")) | D502: =SE(A502="";"";ÍNDICE(Configurações!$B$35:$B$46;MÊS(A502)))

Sheet Doações
A1: 🎁 Doações
A2: Data | B2: Doador | C2: Tipo da Doação | D2: Valor | E2: Conta | F2: Destinação | G2: Observação

Sheet Arrecadação das Missas
A1: ⛪ Arrecadação das Missas
A2: Data | B2: Domingo | C2: Mês | D2: Valor | E2: Conta | F2: Responsável | G2: Observação
A3: 46026 | B3: Domingo 1 | C3: =SE(A3="";"";ÍNDICE(Configurações!$B$35:$B$46;MÊS(A3)))
A4: 46033 | B4: Domingo 2 | C4: =SE(A4="";"";ÍNDICE(Configurações!$B$35:$B$46;MÊS(A4)))
A5: 46040 | B5: Domingo 3 | C5: =SE(A5="";"";ÍNDICE(Configurações!$B$35:$B$46;MÊS(A5)))
A6: 46047 | B6: Domingo 4 | C6: =SE(A6="";"";ÍNDICE(Configurações!$B$35:$B$46;MÊS(A6)))
A7: 46054 | B7: Domingo 5 | C7: =SE(A7="";"";ÍNDICE(Configurações!$B$35:$B$46;MÊS(A7)))
A8: 46061 | B8: Domingo 6 | C8: =SE(A8="";"";ÍNDICE(Configurações!$B$35:$B$46;MÊS(A8)))
A9: 46068 | B9: Domingo 7 | C9: =SE(A9="";"";ÍNDICE(Configurações!$B$35:$B$46;MÊS(A9)))
A10: 46075 | B10: Domingo 8 | C10: =SE(A10="";"";ÍNDICE(Configurações!$B$35:$B$46;MÊS(A10)))
A11: 46082 | B11: Domingo 9 | C11: =SE(A11="";"";ÍNDICE(Configurações!$B$35:$B$46;MÊS(A11)))
A12: 46089 | B12: Domingo 10 | C12: =SE(A12="";"";ÍNDICE(Configurações!$B$35:$B$46;MÊS(A12)))
A13: 46096 | B13: Domingo 11 | C13: =SE(A13="";"";ÍNDICE(Configurações!$B$35:$B$46;MÊS(A13)))
A14: 46103 | B14: Domingo 12 | C14: =SE(A14="";"";ÍNDICE(Configurações!$B$35:$B$46;MÊS(A14)))
... A54: 46383 | B54: Domingo 52 | C54: =SE(A54="";"";ÍNDICE(Configurações!$B$35:$B$46;MÊS(A54)))
C55: =SE(A55="";"";ÍNDICE(Configurações!$B$35:$B$46;MÊS(A55)))
C56: =SE(A56="";"";ÍNDICE(Configurações!$B$35:$B$46;MÊS(A56)))
C57: =SE(A57="";"";ÍNDICE(Configurações!$B$35:$B$46;MÊS(A57)))
C58: =SE(A58="";"";ÍNDICE(Configurações!$B$35:$B$46;MÊS(A58)))
C59: =SE(A59="";"";ÍNDICE(Configurações!$B$35:$B$46;MÊS(A59)))
C60: =SE(A60="";"";ÍNDICE(Configurações!$B$35:$B$46;MÊS(A60)))
C61: =SE(A61="";"";ÍNDICE(Configurações!$B$35:$B$46;MÊS(A61)))
C62: =SE(A62="";"";ÍNDICE(Configurações!$B$35:$B$46;MÊS(A62)))
C63: =SE(A63="";"";ÍNDICE(Configurações!$B$35:$B$46;MÊS(A63)))
C64: =SE(A64="";"";ÍNDICE(Configurações!$B$35:$B$46;MÊS(A64)))
C65: =SE(A65="";"";ÍNDICE(Configurações!$B$35:$B$46;MÊS(A65)))
C66: =SE(A66="";"";ÍNDICE(Configurações!$B$35:$B$46;MÊS(A66)))
... C502: =SE(A502="";"";ÍNDICE(Configurações!$B$35:$B$46;MÊS(A502)))

Sheet Gastos
A1: 💸 Gastos
A2: Data | B2: Categoria | C2: Descrição | D2: Fornecedor | E2: Forma de Pagamento | F2: Valor | G2: Conta | H2: Responsável | I2: Observação

Sheet Contas Caixa e Banco
A1: 💳 Controle de Contas — Caixa e Banco
A2: Conta | B2: Saldo Inicial | C2: Entradas | D2: Saídas | E2: Saldo Atual
A3: Caixa | B3: =Configurações!$B$8 | C3: =SOMASE('Dízimos Mensais'!$G$3:$G$502;A3;'Dízimos Mensais'!$E$3:$E$502)+SOMASE(Doações!$E$3:$E$502;A3;Doações!$D$3:$D$502)+SOMASE('Arrecadação das Missas'!$E$3:$E$502;A3;'Arrecadação das Missas'!$D$3:$D$502) | D3: =SOMASE(Gastos!$G$3:$G$502;A3;Gastos!$F$3:$F$502) | E3: =B3+C3-D3
A4: Banco | B4: =Configurações!$B$9 | C4: =SOMASE('Dízimos Mensais'!$G$3:$G$502;A4;'Dízimos Mensais'!$E$3:$E$502)+SOMASE(Doações!$E$3:$E$502;A4;Doações!$D$3:$D$502)+SOMASE('Arrecadação das Missas'!$E$3:$E$502;A4;'Arrecadação das Missas'!$D$3:$D$502) | D4: =SOMASE(Gastos!$G$3:$G$502;A4;Gastos!$F$3:$F$502) | E4: =B4+C4-D4
A5: TOTAL | B5: =SOMA(B3:B4) | C5: =SOMA(C3:C4) | D5: =SOMA(D3:D4) | E5: =SOMA(E3:E4)

Sheet Resumo Financeiro
A1: 📊 Resumo Financeiro Anual
A2: Mês | B2: Dízimos | C2: Doações | D2: Missas | E2: Total Entradas | F2: Gastos | G2: Saldo do Mês | H2: Meta | I2: % Meta
A3: Janeiro | B3: =SOMASE('Dízimos Mensais'!$D$3:$D$502;A3;'Dízimos Mensais'!$E$3:$E$502) | C3: =SOMASES(Doações!$D$3:$D$502;Doações!$A$3:$A$502;">="&DATA(Configurações!$B$3;1;1);Doações!$A$3:$A$502;"<="&FIM.MÊS(DATA(Configurações!$B$3;1;1))) | D3: =SOMASE('Arrecadação das Missas'!$C$3:$C$502;A3;'Arrecadação das Missas'!$D$3:$D$502) | E3: =SOMA(B3:D3) | F3: =SOMASES(Gastos!$F$3:$F$502;Gastos!$A$3:$A$502;">="&DATA(Configurações!$B$3;1;1);Gastos!$A$3:$A$502;"<="&FIM.MÊS(DATA(Configurações!$B$3;1;1))) | G3: =E3-F3 | H3: =ÍNDICE(Configurações!$B$14:$M$14;1) | I3: =SE(H3=0;"";E3/H3)
A4: Fevereiro | B4: =SOMASE('Dízimos Mensais'!$D$3:$D$502;A4;'Dízimos Mensais'!$E$3:$E$502) | C4: =SOMASES(Doações!$D$3:$D$502;Doações!$A$3:$A$502;">="&DATA(Configurações!$B$3;2;1);Doações!$A$3:$A$502;"<="&FIM.MÊS(DATA(Configurações!$B$3;2;1))) | D4: =SOMASE('Arrecadação das Missas'!$C$3:$C$502;A4;'Arrecadação das Missas'!$D$3:$D$502) | E4: =SOMA(B4:D4) | F4: =SOMASES(Gastos!$F$3:$F$502;Gastos!$A$3:$A$502;">="&DATA(Configurações!$B$3;2;1);Gastos!$A$3:$A$502;"<="&FIM.MÊS(DATA(Configurações!$B$3;2;1))) | G4: =E4-F4 | H4: =ÍNDICE(Configurações!$B$14:$M$14;2) | I4: =SE(H4=0;"";E4/H4)
A5: Março | B5: =SOMASE('Dízimos Mensais'!$D$3:$D$502;A5;'Dízimos Mensais'!$E$3:$E$502) | C5: =SOMASES(Doações!$D$3:$D$502;Doações!$A$3:$A$502;">="&DATA(Configurações!$B$3;3;1);Doações!$A$3:$A$502;"<="&FIM.MÊS(DATA(Configurações!$B$3;3;1))) | D5: =SOMASE('Arrecadação das Missas'!$C$3:$C$502;A5;'Arrecadação das Missas'!$D$3:$D$502) | E5: =SOMA(B5:D5) | F5: =SOMASES(Gastos!$F$3:$F$502;Gastos!$A$3:$A$502;">="&DATA(Configurações!$B$3;3;1);Gastos!$A$3:$A$502;"<="&FIM.MÊS(DATA(Configurações!$B$3;3;1))) | G5: =E5-F5 | H5: =ÍNDICE(Configurações!$B$14:$M$14;3) | I5: =SE(H5=0;"";E5/H5)
A6: Abril | B6: =SOMASE('Dízimos Mensais'!$D$3:$D$502;A6;'Dízimos Mensais'!$E$3:$E$502) | C6: =SOMASES(Doações!$D$3:$D$502;Doações!$A$3:$A$502;">="&DATA(Configurações!$B$3;4;1);Doações!$A$3:$A$502;"<="&FIM.MÊS(DATA(Configurações!$B$3;4;1))) | D6: =SOMASE('Arrecadação das Missas'!$C$3:$C$502;A6;'Arrecadação das Missas'!$D$3:$D$502) | E6: =SOMA(B6:D6) | F6: =SOMASES(Gastos!$F$3:$F$502;Gastos!$A$3:$A$502;">="&DATA(Configurações!$B$3;4;1);Gastos!$A$3:$A$502;"<="&FIM.MÊS(DATA(Configurações!$B$3;4;1))) | G6: =E6-F6 | H6: =ÍNDICE(Configurações!$B$14:$M$14;4) | I6: =SE(H6=0;"";E6/H6)
A7: Maio | B7: =SOMASE('Dízimos Mensais'!$D$3:$D$502;A7;'Dízimos Mensais'!$E$3:$E$502) | C7: =SOMASES(Doações!$D$3:$D$502;Doações!$A$3:$A$502;">="&DATA(Configurações!$B$3;5;1);Doações!$A$3:$A$502;"<="&FIM.MÊS(DATA(Configurações!$B$3;5;1))) | D7: =SOMASE('Arrecadação das Missas'!$C$3:$C$502;A7;'Arrecadação das Missas'!$D$3:$D$502) | E7: =SOMA(B7:D7) | F7: =SOMASES(Gastos!$F$3:$F$502;Gastos!$A$3:$A$502;">="&DATA(Configurações!$B$3;5;1);Gastos!$A$3:$A$502;"<="&FIM.MÊS(DATA(Configurações!$B$3;5;1))) | G7: =E7-F7 | H7: =ÍNDICE(Configurações!$B$14:$M$14;5) | I7: =SE(H7=0;"";E7/H7)
A8: Junho | B8: =SOMASE('Dízimos Mensais'!$D$3:$D$502;A8;'Dízimos Mensais'!$E$3:$E$502) | C8: =SOMASES(Doações!$D$3:$D$502;Doações!$A$3:$A$502;">="&DATA(Configurações!$B$3;6;1);Doações!$A$3:$A$502;"<="&FIM.MÊS(DATA(Configurações!$B$3;6;1))) | D8: =SOMASE('Arrecadação das Missas'!$C$3:$C$502;A8;'Arrecadação das Missas'!$D$3:$D$502) | E8: =SOMA(B8:D8) | F8: =SOMASES(Gastos!$F$3:$F$502;Gastos!$A$3:$A$502;">="&DATA(Configurações!$B$3;6;1);Gastos!$A$3:$A$502;"<="&FIM.MÊS(DATA(Configurações!$B$3;6;1))) | G8: =E8-F8 | H8: =ÍNDICE(Configurações!$B$14:$M$14;6) | I8: =SE(H8=0;"";E8/H8)
A9: Julho | B9: =SOMASE('Dízimos Mensais'!$D$3:$D$502;A9;'Dízimos Mensais'!$E$3:$E$502) | C9: =SOMASES(Doações!$D$3:$D$502;Doações!$A$3:$A$502;">="&DATA(Configurações!$B$3;7;1);Doações!$A$3:$A$502;"<="&FIM.MÊS(DATA(Configurações!$B$3;7;1))) | D9: =SOMASE('Arrecadação das Missas'!$C$3:$C$502;A9;'Arrecadação das Missas'!$D$3:$D$502) | E9: =SOMA(B9:D9) | F9: =SOMASES(Gastos!$F$3:$F$502;Gastos!$A$3:$A$502;">="&DATA(Configurações!$B$3;7;1);Gastos!$A$3:$A$502;"<="&FIM.MÊS(DATA(Configurações!$B$3;7;1))) | G9: =E9-F9 | H9: =ÍNDICE(Configurações!$B$14:$M$14;7) | I9: =SE(H9=0;"";E9/H9)
A10: Agosto | B10: =SOMASE('Dízimos Mensais'!$D$3:$D$502;A10;'Dízimos Mensais'!$E$3:$E$502) | C10: =SOMASES(Doações!$D$3:$D$502;Doações!$A$3:$A$502;">="&DATA(Configurações!$B$3;8;1);Doações!$A$3:$A$502;"<="&FIM.MÊS(DATA(Configurações!$B$3;8;1))) | D10: =SOMASE('Arrecadação das Missas'!$C$3:$C$502;A10;'Arrecadação das Missas'!$D$3:$D$502) | E10: =SOMA(B10:D10) | F10: =SOMASES(Gastos!$F$3:$F$502;Gastos!$A$3:$A$502;">="&DATA(Configurações!$B$3;8;1);Gastos!$A$3:$A$502;"<="&FIM.MÊS(DATA(Configurações!$B$3;8;1))) | G10: =E10-F10 | H10: =ÍNDICE(Configurações!$B$14:$M$14;8) | I10: =SE(H10=0;"";E10/H10)
A11: Setembro | B11: =SOMASE('Dízimos Mensais'!$D$3:$D$502;A11;'Dízimos Mensais'!$E$3:$E$502) | C11: =SOMASES(Doações!$D$3:$D$502;Doações!$A$3:$A$502;">="&DATA(Configurações!$B$3;9;1);Doações!$A$3:$A$502;"<="&FIM.MÊS(DATA(Configurações!$B$3;9;1))) | D11: =SOMASE('Arrecadação das Missas'!$C$3:$C$502;A11;'Arrecadação das Missas'!$D$3:$D$502) | E11: =SOMA(B11:D11) | F11: =SOMASES(Gastos!$F$3:$F$502;Gastos!$A$3:$A$502;">="&DATA(Configurações!$B$3;9;1);Gastos!$A$3:$A$502;"<="&FIM.MÊS(DATA(Configurações!$B$3;9;1))) | G11: =E11-F11 | H11: =ÍNDICE(Configurações!$B$14:$M$14;9) | I11: =SE(H11=0;"";E11/H11)
A12: Outubro | B12: =SOMASE('Dízimos Mensais'!$D$3:$D$502;A12;'Dízimos Mensais'!$E$3:$E$502) | C12: =SOMASES(Doações!$D$3:$D$502;Doações!$A$3:$A$502;">="&DATA(Configurações!$B$3;10;1);Doações!$A$3:$A$502;"<="&FIM.MÊS(DATA(Configurações!$B$3;10;1))) | D12: =SOMASE('Arrecadação das Missas'!$C$3:$C$502;A12;'Arrecadação das Missas'!$D$3:$D$502) | E12: =SOMA(B12:D12) | F12: =SOMASES(Gastos!$F$3:$F$502;Gastos!$A$3:$A$502;">="&DATA(Configurações!$B$3;10;1);Gastos!$A$3:$A$502;"<="&FIM.MÊS(DATA(Configurações!$B$3;10;1))) | G12: =E12-F12 | H12: =ÍNDICE(Configurações!$B$14:$M$14;10) | I12: =SE(H12=0;"";E12/H12)
A13: Novembro | B13: =SOMASE('Dízimos Mensais'!$D$3:$D$502;A13;'Dízimos Mensais'!$E$3:$E$502) | C13: =SOMASES(Doações!$D$3:$D$502;Doações!$A$3:$A$502;">="&DATA(Configurações!$B$3;11;1);Doações!$A$3:$A$502;"<="&FIM.MÊS(DATA(Configurações!$B$3;11;1))) | D13: =SOMASE('Arrecadação das Missas'!$C$3:$C$502;A13;'Arrecadação das Missas'!$D$3:$D$502) | E13: =SOMA(B13:D13) | F13: =SOMASES(Gastos!$F$3:$F$502;Gastos!$A$3:$A$502;">="&DATA(Configurações!$B$3;11;1);Gastos!$A$3:$A$502;"<="&FIM.MÊS(DATA(Configurações!$B$3;11;1))) | G13: =E13-F13 | H13: =ÍNDICE(Configurações!$B$14:$M$14;11) | I13: =SE(H13=0;"";E13/H13)
A14: Dezembro | B14: =SOMASE('Dízimos Mensais'!$D$3:$D$502;A14;'Dízimos Mensais'!$E$3:$E$502) | C14: =SOMASES(Doações!$D$3:$D$502;Doações!$A$3:$A$502;">="&DATA(Configurações!$B$3;12;1);Doações!$A$3:$A$502;"<="&FIM.MÊS(DATA(Configurações!$B$3;12;1))) | D14: =SOMASE('Arrecadação das Missas'!$C$3:$C$502;A14;'Arrecadação das Missas'!$D$3:$D$502) | E14: =SOMA(B14:D14) | F14: =SOMASES(Gastos!$F$3:$F$502;Gastos!$A$3:$A$502;">="&DATA(Configurações!$B$3;12;1);Gastos!$A$3:$A$502;"<="&FIM.MÊS(DATA(Configurações!$B$3;12;1))) | G14: =E14-F14 | H14: =ÍNDICE(Configurações!$B$14:$M$14;12) | I14: =SE(H14=0;"";E14/H14)
A15: TOTAL ANUAL | B15: =SOMA(B3:B14) | C15: =SOMA(C3:C14) | D15: =SOMA(D3:D14) | E15: =SOMA(E3:E14) | F15: =SOMA(F3:F14) | G15: =SOMA(G3:G14) | H15: =SOMA(H3:H14)

Sheet Conciliação Bancária
A1: 🏦 Conciliação Bancária
A2: Data | B2: Descrição | C2: Valor Planilha | D2: Valor Extrato | E2: Diferença | F2: Conferido
E3: =SE(OU(A3="";C3="";D3="");"";C3-D3) | F3: =SE(OU(A3="";C3="";D3="");"";SE(C3=D3;"✅";"❌"))
E4: =SE(OU(A4="";C4="";D4="");"";C4-D4) | F4: =SE(OU(A4="";C4="";D4="");"";SE(C4=D4;"✅";"❌"))
E5: =SE(OU(A5="";C5="";D5="");"";C5-D5) | F5: =SE(OU(A5="";C5="";D5="");"";SE(C5=D5;"✅";"❌"))
E6: =SE(OU(A6="";C6="";D6="");"";C6-D6) | F6: =SE(OU(A6="";C6="";D6="");"";SE(C6=D6;"✅";"❌"))
E7: =SE(OU(A7="";C7="";D7="");"";C7-D7) | F7: =SE(OU(A7="";C7="";D7="");"";SE(C7=D7;"✅";"❌"))
E8: =SE(OU(A8="";C8="";D8="");"";C8-D8) | F8: =SE(OU(A8="";C8="";D8="");"";SE(C8=D8;"✅";"❌"))
E9: =SE(OU(A9="";C9="";D9="");"";C9-D9) | F9: =SE(OU(A9="";C9="";D9="");"";SE(C9=D9;"✅";"❌"))
E10: =SE(OU(A10="";C10="";D10="");"";C10-D10) | F10: =SE(OU(A10="";C10="";D10="");"";SE(C10=D10;"✅";"❌"))
E11: =SE(OU(A11="";C11="";D11="");"";C11-D11) | F11: =SE(OU(A11="";C11="";D11="");"";SE(C11=D11;"✅";"❌"))
E12: =SE(OU(A12="";C12="";D12="");"";C12-D12) | F12: =SE(OU(A12="";C12="";D12="");"";SE(C12=D12;"✅";"❌"))
E13: =SE(OU(A13="";C13="";D13="");"";C13-D13) | F13: =SE(OU(A13="";C13="";D13="");"";SE(C13=D13;"✅";"❌"))
E14: =SE(OU(A14="";C14="";D14="");"";C14-D14) | F14: =SE(OU(A14="";C14="";D14="");"";SE(C14=D14;"✅";"❌"))
... E502: =SE(OU(A502="";C502="";D502="");"";C502-D502) | F502: =SE(OU(A502="";C502="";D502="");"";SE(C502=D502;"✅";"❌"))

Sheet Relatório Anual
A1: 📑 Relatório Anual — Prestação de Contas
A3: RECEITAS
A4: Total de Dízimos | B4: ='Resumo Financeiro'!B15
A5: Total de Doações | B5: ='Resumo Financeiro'!C15
A6: Total Coletas de Domingo (Missas) | B6: ='Resumo Financeiro'!D15
A7: Outras Receitas | B7: 0
A8: TOTAL DE RECEITAS | B8: ='Resumo Financeiro'!E15
A10: DESPESAS
A11: Água | B11: =SOMASE(Gastos!$B$3:$B$502;A11;Gastos!$F$3:$F$502)
A12: Energia | B12: =SOMASE(Gastos!$B$3:$B$502;A12;Gastos!$F$3:$F$502)
A13: Limpeza | B13: =SOMASE(Gastos!$B$3:$B$502;A13;Gastos!$F$3:$F$502)
A14: Material Litúrgico | B14: =SOMASE(Gastos!$B$3:$B$502;A14;Gastos!$F$3:$F$502)
A15: Hóstias | B15: =SOMASE(Gastos!$B$3:$B$502;A15;Gastos!$F$3:$F$502)
A16: Vinho | B16: =SOMASE(Gastos!$B$3:$B$502;A16;Gastos!$F$3:$F$502)
A17: Flores | B17: =SOMASE(Gastos!$B$3:$B$502;A17;Gastos!$F$3:$F$502)
A18: Som | B18: =SOMASE(Gastos!$B$3:$B$502;A18;Gastos!$F$3:$F$502)
A19: Manutenção | B19: =SOMASE(Gastos!$B$3:$B$502;A19;Gastos!$F$3:$F$502)
A20: Obras | B20: =SOMASE(Gastos!$B$3:$B$502;A20;Gastos!$F$3:$F$502)
A21: Secretaria | B21: =SOMASE(Gastos!$B$3:$B$502;A21;Gastos!$F$3:$F$502)
A22: Eventos | B22: =SOMASE(Gastos!$B$3:$B$502;A22;Gastos!$F$3:$F$502)
... A25: Outros | B25: =SOMASE(Gastos!$B$3:$B$502;A25;Gastos!$F$3:$F$502)
A26: TOTAL DE DESPESAS | B26: ='Resumo Financeiro'!F15
A28: RESULTADO DO EXERCÍCIO
A29: Saldo Inicial | B29: =Configurações!$B$10
A30: (+) Total Receitas | B30: ='Resumo Financeiro'!E15
A31: (-) Total Despesas | B31: ='Resumo Financeiro'!F15
A32: (=) Saldo Final | B32: =Configurações!$B$10+'Resumo Financeiro'!G15
A34: Ano de referência: | B34: =Configurações!$B$3

Sheet Relatório Despesas
A1: 📑 Relatório por Categoria de Despesas
A2: Categoria | B2: Jan | C2: Fev | D2: Mar | E2: Abr | F2: Mai | G2: Jun | H2: Jul | I2: Ago | J2: Set | K2: Out | L2: Nov | M2: Dez | N2: Total Anual | O2: % do Total
A3: Água | B3: =SOMASES(Gastos!$F$3:$F$502;Gastos!$B$3:$B$502;$A3;Gastos!$A$3:$A$502;">="&DATA(Configurações!$B$3;1;1);Gastos!$A$3:$A$502;"<="&FIM.MÊS(DATA(Configurações!$B$3;1;1))) | C3: =SOMASES(Gastos!$F$3:$F$502;Gastos!$B$3:$B$502;$A3;Gastos!$A$3:$A$502;">="&DATA(Configurações!$B$3;2;1);Gastos!$A$3:$A$502;"<="&FIM.MÊS(DATA(Configurações!$B$3;2;1))) | D3: =SOMASES(Gastos!$F$3:$F$502;Gastos!$B$3:$B$502;$A3;Gastos!$A$3:$A$502;">="&DATA(Configurações!$B$3;3;1);Gastos!$A$3:$A$502;"<="&FIM.MÊS(DATA(Configurações!$B$3;3;1))) | E3: =SOMASES(Gastos!$F$3:$F$502;Gastos!$B$3:$B$502;$A3;Gastos!$A$3:$A$502;">="&DATA(Configurações!$B$3;4;1);Gastos!$A$3:$A$502;"<="&FIM.MÊS(DATA(Configurações!$B$3;4;1))) | F3: =SOMASES(Gastos!$F$3:$F$502;Gastos!$B$3:$B$502;$A3;Gastos!$A$3:$A$502;">="&DATA(Configurações!$B$3;5;1);Gastos!$A$3:$A$502;"<="&FIM.MÊS(DATA(Configurações!$B$3;5;1))) | G3: =SOMASES(Gastos!$F$3:$F$502;Gastos!$B$3:$B$502;$A3;Gastos!$A$3:$A$502;">="&DATA(Configurações!$B$3;6;1);Gastos!$A$3:$A$502;"<="&FIM.MÊS(DATA(Configurações!$B$3;6;1))) | H3: =SOMASES(Gastos!$F$3:$F$502;Gastos!$B$3:$B$502;$A3;Gastos!$A$3:$A$502;">="&DATA(Configurações!$B$3;7;1);Gastos!$A$3:$A$502;"<="&FIM.MÊS(DATA(Configurações!$B$3;7;1))) | I3: =SOMASES(Gastos!$F$3:$F$502;Gastos!$B$3:$B$502;$A3;Gastos!$A$3:$A$502;">="&DATA(Configurações!$B$3;8;1);Gastos!$A$3:$A$502;"<="&FIM.MÊS(DATA(Configurações!$B$3;8;1))) | J3: =SOMASES(Gastos!$F$3:$F$502;Gastos!$B$3:$B$502;$A3;Gastos!$A$3:$A$502;">="&DATA(Configurações!$B$3;9;1);Gastos!$A$3:$A$502;"<="&FIM.MÊS(DATA(Configurações!$B$3;9;1))) | K3: =SOMASES(Gastos!$F$3:$F$502;Gastos!$B$3:$B$502;$A3;Gastos!$A$3:$A$502;">="&DATA(Configurações!$B$3;10;1);Gastos!$A$3:$A$502;"<="&FIM.MÊS(DATA(Configurações!$B$3;10;1))) | L3: =SOMASES(Gastos!$F$3:$F$502;Gastos!$B$3:$B$502;$A3;Gastos!$A$3:$A$502;">="&DATA(Configurações!$B$3;11;1);Gastos!$A$3:$A$502;"<="&FIM.MÊS(DATA(Configurações!$B$3;11;1))) | M3: =SOMASES(Gastos!$F$3:$F$502;Gastos!$B$3:$B$502;$A3;Gastos!$A$3:$A$502;">="&DATA(Configurações!$B$3;12;1);Gastos!$A$3:$A$502;"<="&FIM.MÊS(DATA(Configurações!$B$3;12;1))) | N3: =SOMA(B3:M3) | O3: =SE(N$18=0;"";N3/N$18)
A4: Energia | B4: =SOMASES(Gastos!$F$3:$F$502;Gastos!$B$3:$B$502;$A4;Gastos!$A$3:$A$502;">="&DATA(Configurações!$B$3;1;1);Gastos!$A$3:$A$502;"<="&FIM.MÊS(DATA(Configurações!$B$3;1;1))) | C4: =SOMASES(Gastos!$F$3:$F$502;Gastos!$B$3:$B$502;$A4;Gastos!$A$3:$A$502;">="&DATA(Configurações!$B$3;2;1);Gastos!$A$3:$A$502;"<="&FIM.MÊS(DATA(Configurações!$B$3;2;1))) | D4: =SOMASES(Gastos!$F$3:$F$502;Gastos!$B$3:$B$502;$A4;Gastos!$A$3:$A$502;">="&DATA(Configurações!$B$3;3;1);Gastos!$A$3:$A$502;"<="&FIM.MÊS(DATA(Configurações!$B$3;3;1))) | E4: =SOMASES(Gastos!$F$3:$F$502;Gastos!$B$3:$B$502;$A4;Gastos!$A$3:$A$502;">="&DATA(Configurações!$B$3;4;1);Gastos!$A$3:$A$502;"<="&FIM.MÊS(DATA(Configurações!$B$3;4;1))) | F4: =SOMASES(Gastos!$F$3:$F$502;Gastos!$B$3:$B$502;$A4;Gastos!$A$3:$A$502;">="&DATA(Configurações!$B$3;5;1);Gastos!$A$3:$A$502;"<="&FIM.MÊS(DATA(Configurações!$B$3;5;1))) | G4: =SOMASES(Gastos!$F$3:$F$502;Gastos!$B$3:$B$502;$A4;Gastos!$A$3:$A$502;">="&DATA(Configurações!$B$3;6;1);Gastos!$A$3:$A$502;"<="&FIM.MÊS(DATA(Configurações!$B$3;6;1))) | H4: =SOMASES(Gastos!$F$3:$F$502;Gastos!$B$3:$B$502;$A4;Gastos!$A$3:$A$502;">="&DATA(Configurações!$B$3;7;1);Gastos!$A$3:$A$502;"<="&FIM.MÊS(DATA(Configurações!$B$3;7;1))) | I4: =SOMASES(Gastos!$F$3:$F$502;Gastos!$B$3:$B$502;$A4;Gastos!$A$3:$A$502;">="&DATA(Configurações!$B$3;8;1);Gastos!$A$3:$A$502;"<="&FIM.MÊS(DATA(Configurações!$B$3;8;1))) | J4: =SOMASES(Gastos!$F$3:$F$502;Gastos!$B$3:$B$502;$A4;Gastos!$A$3:$A$502;">="&DATA(Configurações!$B$3;9;1);Gastos!$A$3:$A$502;"<="&FIM.MÊS(DATA(Configurações!$B$3;9;1))) | K4: =SOMASES(Gastos!$F$3:$F$502;Gastos!$B$3:$B$502;$A4;Gastos!$A$3:$A$502;">="&DATA(Configurações!$B$3;10;1);Gastos!$A$3:$A$502;"<="&FIM.MÊS(DATA(Configurações!$B$3;10;1))) | L4: =SOMASES(Gastos!$F$3:$F$502;Gastos!$B$3:$B$502;$A4;Gastos!$A$3:$A$502;">="&DATA(Configurações!$B$3;11;1);Gastos!$A$3:$A$502;"<="&FIM.MÊS(DATA(Configurações!$B$3;11;1))) | M4: =SOMASES(Gastos!$F$3:$F$502;Gastos!$B$3:$B$502;$A4;Gastos!$A$3:$A$502;">="&DATA(Configurações!$B$3;12;1);Gastos!$A$3:$A$502;"<="&FIM.MÊS(DATA(Configurações!$B$3;12;1))) | N4: =SOMA(B4:M4) | O4: =SE(N$18=0;"";N4/N$18)
A5: Limpeza | B5: =SOMASES(Gastos!$F$3:$F$502;Gastos!$B$3:$B$502;$A5;Gastos!$A$3:$A$502;">="&DATA(Configurações!$B$3;1;1);Gastos!$A$3:$A$502;"<="&FIM.MÊS(DATA(Configurações!$B$3;1;1))) | C5: =SOMASES(Gastos!$F$3:$F$502;Gastos!$B$3:$B$502;$A5;Gastos!$A$3:$A$502;">="&DATA(Configurações!$B$3;2;1);Gastos!$A$3:$A$502;"<="&FIM.MÊS(DATA(Configurações!$B$3;2;1))) | D5: =SOMASES(Gastos!$F$3:$F$502;Gastos!$B$3:$B$502;$A5;Gastos!$A$3:$A$502;">="&DATA(Configurações!$B$3;3;1);Gastos!$A$3:$A$502;"<="&FIM.MÊS(DATA(Configurações!$B$3;3;1))) | E5: =SOMASES(Gastos!$F$3:$F$502;Gastos!$B$3:$B$502;$A5;Gastos!$A$3:$A$502;">="&DATA(Configurações!$B$3;4;1);Gastos!$A$3:$A$502;"<="&FIM.MÊS(DATA(Configurações!$B$3;4;1))) | F5: =SOMASES(Gastos!$F$3:$F$502;Gastos!$B$3:$B$502;$A5;Gastos!$A$3:$A$502;">="&DATA(Configurações!$B$3;5;1);Gastos!$A$3:$A$502;"<="&FIM.MÊS(DATA(Configurações!$B$3;5;1))) | G5: =SOMASES(Gastos!$F$3:$F$502;Gastos!$B$3:$B$502;$A5;Gastos!$A$3:$A$502;">="&DATA(Configurações!$B$3;6;1);Gastos!$A$3:$A$502;"<="&FIM.MÊS(DATA(Configurações!$B$3;6;1))) | H5: =SOMASES(Gastos!$F$3:$F$502;Gastos!$B$3:$B$502;$A5;Gastos!$A$3:$A$502;">="&DATA(Configurações!$B$3;7;1);Gastos!$A$3:$A$502;"<="&FIM.MÊS(DATA(Configurações!$B$3;7;1))) | I5: =SOMASES(Gastos!$F$3:$F$502;Gastos!$B$3:$B$502;$A5;Gastos!$A$3:$A$502;">="&DATA(Configurações!$B$3;8;1);Gastos!$A$3:$A$502;"<="&FIM.MÊS(DATA(Configurações!$B$3;8;1))) | J5: =SOMASES(Gastos!$F$3:$F$502;Gastos!$B$3:$B$502;$A5;Gastos!$A$3:$A$502;">="&DATA(Configurações!$B$3;9;1);Gastos!$A$3:$A$502;"<="&FIM.MÊS(DATA(Configurações!$B$3;9;1))) | K5: =SOMASES(Gastos!$F$3:$F$502;Gastos!$B$3:$B$502;$A5;Gastos!$A$3:$A$502;">="&DATA(Configurações!$B$3;10;1);Gastos!$A$3:$A$502;"<="&FIM.MÊS(DATA(Configurações!$B$3;10;1))) | L5: =SOMASES(Gastos!$F$3:$F$502;Gastos!$B$3:$B$502;$A5;Gastos!$A$3:$A$502;">="&DATA(Configurações!$B$3;11;1);Gastos!$A$3:$A$502;"<="&FIM.MÊS(DATA(Configurações!$B$3;11;1))) | M5: =SOMASES(Gastos!$F$3:$F$502;Gastos!$B$3:$B$502;$A5;Gastos!$A$3:$A$502;">="&DATA(Configurações!$B$3;12;1);Gastos!$A$3:$A$502;"<="&FIM.MÊS(DATA(Configurações!$B$3;12;1))) | N5: =SOMA(B5:M5) | O5: =SE(N$18=0;"";N5/N$18)
A6: Material Litúrgico | B6: =SOMASES(Gastos!$F$3:$F$502;Gastos!$B$3:$B$502;$A6;Gastos!$A$3:$A$502;">="&DATA(Configurações!$B$3;1;1);Gastos!$A$3:$A$502;"<="&FIM.MÊS(DATA(Configurações!$B$3;1;1))) | C6: =SOMASES(Gastos!$F$3:$F$502;Gastos!$B$3:$B$502;$A6;Gastos!$A$3:$A$502;">="&DATA(Configurações!$B$3;2;1);Gastos!$A$3:$A$502;"<="&FIM.MÊS(DATA(Configurações!$B$3;2;1))) | D6: =SOMASES(Gastos!$F$3:$F$502;Gastos!$B$3:$B$502;$A6;Gastos!$A$3:$A$502;">="&DATA(Configurações!$B$3;3;1);Gastos!$A$3:$A$502;"<="&FIM.MÊS(DATA(Configurações!$B$3;3;1))) | E6: =SOMASES(Gastos!$F$3:$F$502;Gastos!$B$3:$B$502;$A6;Gastos!$A$3:$A$502;">="&DATA(Configurações!$B$3;4;1);Gastos!$A$3:$A$502;"<="&FIM.MÊS(DATA(Configurações!$B$3;4;1))) | F6: =SOMASES(Gastos!$F$3:$F$502;Gastos!$B$3:$B$502;$A6;Gastos!$A$3:$A$502;">="&DATA(Configurações!$B$3;5;1);Gastos!$A$3:$A$502;"<="&FIM.MÊS(DATA(Configurações!$B$3;5;1))) | G6: =SOMASES(Gastos!$F$3:$F$502;Gastos!$B$3:$B$502;$A6;Gastos!$A$3:$A$502;">="&DATA(Configurações!$B$3;6;1);Gastos!$A$3:$A$502;"<="&FIM.MÊS(DATA(Configurações!$B$3;6;1))) | H6: =SOMASES(Gastos!$F$3:$F$502;Gastos!$B$3:$B$502;$A6;Gastos!$A$3:$A$502;">="&DATA(Configurações!$B$3;7;1);Gastos!$A$3:$A$502;"<="&FIM.MÊS(DATA(Configurações!$B$3;7;1))) | I6: =SOMASES(Gastos!$F$3:$F$502;Gastos!$B$3:$B$502;$A6;Gastos!$A$3:$A$502;">="&DATA(Configurações!$B$3;8;1);Gastos!$A$3:$A$502;"<="&FIM.MÊS(DATA(Configurações!$B$3;8;1))) | J6: =SOMASES(Gastos!$F$3:$F$502;Gastos!$B$3:$B$502;$A6;Gastos!$A$3:$A$502;">="&DATA(Configurações!$B$3;9;1);Gastos!$A$3:$A$502;"<="&FIM.MÊS(DATA(Configurações!$B$3;9;1))) | K6: =SOMASES(Gastos!$F$3:$F$502;Gastos!$B$3:$B$502;$A6;Gastos!$A$3:$A$502;">="&DATA(Configurações!$B$3;10;1);Gastos!$A$3:$A$502;"<="&FIM.MÊS(DATA(Configurações!$B$3;10;1))) | L6: =SOMASES(Gastos!$F$3:$F$502;Gastos!$B$3:$B$502;$A6;Gastos!$A$3:$A$502;">="&DATA(Configurações!$B$3;11;1);Gastos!$A$3:$A$502;"<="&FIM.MÊS(DATA(Configurações!$B$3;11;1))) | M6: =SOMASES(Gastos!$F$3:$F$502;Gastos!$B$3:$B$502;$A6;Gastos!$A$3:$A$502;">="&DATA(Configurações!$B$3;12;1);Gastos!$A$3:$A$502;"<="&FIM.MÊS(DATA(Configurações!$B$3;12;1))) | N6: =SOMA(B6:M6) | O6: =SE(N$18=0;"";N6/N$18)
A7: Hóstias | B7: =SOMASES(Gastos!$F$3:$F$502;Gastos!$B$3:$B$502;$A7;Gastos!$A$3:$A$502;">="&DATA(Configurações!$B$3;1;1);Gastos!$A$3:$A$502;"<="&FIM.MÊS(DATA(Configurações!$B$3;1;1))) | C7: =SOMASES(Gastos!$F$3:$F$502;Gastos!$B$3:$B$502;$A7;Gastos!$A$3:$A$502;">="&DATA(Configurações!$B$3;2;1);Gastos!$A$3:$A$502;"<="&FIM.MÊS(DATA(Configurações!$B$3;2;1))) | D7: =SOMASES(Gastos!$F$3:$F$502;Gastos!$B$3:$B$502;$A7;Gastos!$A$3:$A$502;">="&DATA(Configurações!$B$3;3;1);Gastos!$A$3:$A$502;"<="&FIM.MÊS(DATA(Configurações!$B$3;3;1))) | E7: =SOMASES(Gastos!$F$3:$F$502;Gastos!$B$3:$B$502;$A7;Gastos!$A$3:$A$502;">="&DATA(Configurações!$B$3;4;1);Gastos!$A$3:$A$502;"<="&FIM.MÊS(DATA(Configurações!$B$3;4;1))) | F7: =SOMASES(Gastos!$F$3:$F$502;Gastos!$B$3:$B$502;$A7;Gastos!$A$3:$A$502;">="&DATA(Configurações!$B$3;5;1);Gastos!$A$3:$A$502;"<="&FIM.MÊS(DATA(Configurações!$B$3;5;1))) | G7: =SOMASES(Gastos!$F$3:$F$502;Gastos!$B$3:$B$502;$A7;Gastos!$A$3:$A$502;">="&DATA(Configurações!$B$3;6;1);Gastos!$A$3:$A$502;"<="&FIM.MÊS(DATA(Configurações!$B$3;6;1))) | H7: =SOMASES(Gastos!$F$3:$F$502;Gastos!$B$3:$B$502;$A7;Gastos!$A$3:$A$502;">="&DATA(Configurações!$B$3;7;1);Gastos!$A$3:$A$502;"<="&FIM.MÊS(DATA(Configurações!$B$3;7;1))) | I7: =SOMASES(Gastos!$F$3:$F$502;Gastos!$B$3:$B$502;$A7;Gastos!$A$3:$A$502;">="&DATA(Configurações!$B$3;8;1);Gastos!$A$3:$A$502;"<="&FIM.MÊS(DATA(Configurações!$B$3;8;1))) | J7: =SOMASES(Gastos!$F$3:$F$502;Gastos!$B$3:$B$502;$A7;Gastos!$A$3:$A$502;">="&DATA(Configurações!$B$3;9;1);Gastos!$A$3:$A$502;"<="&FIM.MÊS(DATA(Configurações!$B$3;9;1))) | K7: =SOMASES(Gastos!$F$3:$F$502;Gastos!$B$3:$B$502;$A7;Gastos!$A$3:$A$502;">="&DATA(Configurações!$B$3;10;1);Gastos!$A$3:$A$502;"<="&FIM.MÊS(DATA(Configurações!$B$3;10;1))) | L7: =SOMASES(Gastos!$F$3:$F$502;Gastos!$B$3:$B$502;$A7;Gastos!$A$3:$A$502;">="&DATA(Configurações!$B$3;11;1);Gastos!$A$3:$A$502;"<="&FIM.MÊS(DATA(Configurações!$B$3;11;1))) | M7: =SOMASES(Gastos!$F$3:$F$502;Gastos!$B$3:$B$502;$A7;Gastos!$A$3:$A$502;">="&DATA(Configurações!$B$3;12;1);Gastos!$A$3:$A$502;"<="&FIM.MÊS(DATA(Configurações!$B$3;12;1))) | N7: =SOMA(B7:M7) | O7: =SE(N$18=0;"";N7/N$18)
A8: Vinho | B8: =SOMASES(Gastos!$F$3:$F$502;Gastos!$B$3:$B$502;$A8;Gastos!$A$3:$A$502;">="&DATA(Configurações!$B$3;1;1);Gastos!$A$3:$A$502;"<="&FIM.MÊS(DATA(Configurações!$B$3;1;1))) | C8: =SOMASES(Gastos!$F$3:$F$502;Gastos!$B$3:$B$502;$A8;Gastos!$A$3:$A$502;">="&DATA(Configurações!$B$3;2;1);Gastos!$A$3:$A$502;"<="&FIM.MÊS(DATA(Configurações!$B$3;2;1))) | D8: =SOMASES(Gastos!$F$3:$F$502;Gastos!$B$3:$B$502;$A8;Gastos!$A$3:$A$502;">="&DATA(Configurações!$B$3;3;1);Gastos!$A$3:$A$502;"<="&FIM.MÊS(DATA(Configurações!$B$3;3;1))) | E8: =SOMASES(Gastos!$F$3:$F$502;Gastos!$B$3:$B$502;$A8;Gastos!$A$3:$A$502;">="&DATA(Configurações!$B$3;4;1);Gastos!$A$3:$A$502;"<="&FIM.MÊS(DATA(Configurações!$B$3;4;1))) | F8: =SOMASES(Gastos!$F$3:$F$502;Gastos!$B$3:$B$502;$A8;Gastos!$A$3:$A$502;">="&DATA(Configurações!$B$3;5;1);Gastos!$A$3:$A$502;"<="&FIM.MÊS(DATA(Configurações!$B$3;5;1))) | G8: =SOMASES(Gastos!$F$3:$F$502;Gastos!$B$3:$B$502;$A8;Gastos!$A$3:$A$502;">="&DATA(Configurações!$B$3;6;1);Gastos!$A$3:$A$502;"<="&FIM.MÊS(DATA(Configurações!$B$3;6;1))) | H8: =SOMASES(Gastos!$F$3:$F$502;Gastos!$B$3:$B$502;$A8;Gastos!$A$3:$A$502;">="&DATA(Configurações!$B$3;7;1);Gastos!$A$3:$A$502;"<="&FIM.MÊS(DATA(Configurações!$B$3;7;1))) | I8: =SOMASES(Gastos!$F$3:$F$502;Gastos!$B$3:$B$502;$A8;Gastos!$A$3:$A$502;">="&DATA(Configurações!$B$3;8;1);Gastos!$A$3:$A$502;"<="&FIM.MÊS(DATA(Configurações!$B$3;8;1))) | J8: =SOMASES(Gastos!$F$3:$F$502;Gastos!$B$3:$B$502;$A8;Gastos!$A$3:$A$502;">="&DATA(Configurações!$B$3;9;1);Gastos!$A$3:$A$502;"<="&FIM.MÊS(DATA(Configurações!$B$3;9;1))) | K8: =SOMASES(Gastos!$F$3:$F$502;Gastos!$B$3:$B$502;$A8;Gastos!$A$3:$A$502;">="&DATA(Configurações!$B$3;10;1);Gastos!$A$3:$A$502;"<="&FIM.MÊS(DATA(Configurações!$B$3;10;1))) | L8: =SOMASES(Gastos!$F$3:$F$502;Gastos!$B$3:$B$502;$A8;Gastos!$A$3:$A$502;">="&DATA(Configurações!$B$3;11;1);Gastos!$A$3:$A$502;"<="&FIM.MÊS(DATA(Configurações!$B$3;11;1))) | M8: =SOMASES(Gastos!$F$3:$F$502;Gastos!$B$3:$B$502;$A8;Gastos!$A$3:$A$502;">="&DATA(Configurações!$B$3;12;1);Gastos!$A$3:$A$502;"<="&FIM.MÊS(DATA(Configurações!$B$3;12;1))) | N8: =SOMA(B8:M8) | O8: =SE(N$18=0;"";N8/N$18)
A9: Flores | B9: =SOMASES(Gastos!$F$3:$F$502;Gastos!$B$3:$B$502;$A9;Gastos!$A$3:$A$502;">="&DATA(Configurações!$B$3;1;1);Gastos!$A$3:$A$502;"<="&FIM.MÊS(DATA(Configurações!$B$3;1;1))) | C9: =SOMASES(Gastos!$F$3:$F$502;Gastos!$B$3:$B$502;$A9;Gastos!$A$3:$A$502;">="&DATA(Configurações!$B$3;2;1);Gastos!$A$3:$A$502;"<="&FIM.MÊS(DATA(Configurações!$B$3;2;1))) | D9: =SOMASES(Gastos!$F$3:$F$502;Gastos!$B$3:$B$502;$A9;Gastos!$A$3:$A$502;">="&DATA(Configurações!$B$3;3;1);Gastos!$A$3:$A$502;"<="&FIM.MÊS(DATA(Configurações!$B$3;3;1))) | E9: =SOMASES(Gastos!$F$3:$F$502;Gastos!$B$3:$B$502;$A9;Gastos!$A$3:$A$502;">="&DATA(Configurações!$B$3;4;1);Gastos!$A$3:$A$502;"<="&FIM.MÊS(DATA(Configurações!$B$3;4;1))) | F9: =SOMASES(Gastos!$F$3:$F$502;Gastos!$B$3:$B$502;$A9;Gastos!$A$3:$A$502;">="&DATA(Configurações!$B$3;5;1);Gastos!$A$3:$A$502;"<="&FIM.MÊS(DATA(Configurações!$B$3;5;1))) | G9: =SOMASES(Gastos!$F$3:$F$502;Gastos!$B$3:$B$502;$A9;Gastos!$A$3:$A$502;">="&DATA(Configurações!$B$3;6;1);Gastos!$A$3:$A$502;"<="&FIM.MÊS(DATA(Configurações!$B$3;6;1))) | H9: =SOMASES(Gastos!$F$3:$F$502;Gastos!$B$3:$B$502;$A9;Gastos!$A$3:$A$502;">="&DATA(Configurações!$B$3;7;1);Gastos!$A$3:$A$502;"<="&FIM.MÊS(DATA(Configurações!$B$3;7;1))) | I9: =SOMASES(Gastos!$F$3:$F$502;Gastos!$B$3:$B$502;$A9;Gastos!$A$3:$A$502;">="&DATA(Configurações!$B$3;8;1);Gastos!$A$3:$A$502;"<="&FIM.MÊS(DATA(Configurações!$B$3;8;1))) | J9: =SOMASES(Gastos!$F$3:$F$502;Gastos!$B$3:$B$502;$A9;Gastos!$A$3:$A$502;">="&DATA(Configurações!$B$3;9;1);Gastos!$A$3:$A$502;"<="&FIM.MÊS(DATA(Configurações!$B$3;9;1))) | K9: =SOMASES(Gastos!$F$3:$F$502;Gastos!$B$3:$B$502;$A9;Gastos!$A$3:$A$502;">="&DATA(Configurações!$B$3;10;1);Gastos!$A$3:$A$502;"<="&FIM.MÊS(DATA(Configurações!$B$3;10;1))) | L9: =SOMASES(Gastos!$F$3:$F$502;Gastos!$B$3:$B$502;$A9;Gastos!$A$3:$A$502;">="&DATA(Configurações!$B$3;11;1);Gastos!$A$3:$A$502;"<="&FIM.MÊS(DATA(Configurações!$B$3;11;1))) | M9: =SOMASES(Gastos!$F$3:$F$502;Gastos!$B$3:$B$502;$A9;Gastos!$A$3:$A$502;">="&DATA(Configurações!$B$3;12;1);Gastos!$A$3:$A$502;"<="&FIM.MÊS(DATA(Configurações!$B$3;12;1))) | N9: =SOMA(B9:M9) | O9: =SE(N$18=0;"";N9/N$18)
A10: Som | B10: =SOMASES(Gastos!$F$3:$F$502;Gastos!$B$3:$B$502;$A10;Gastos!$A$3:$A$502;">="&DATA(Configurações!$B$3;1;1);Gastos!$A$3:$A$502;"<="&FIM.MÊS(DATA(Configurações!$B$3;1;1))) | C10: =SOMASES(Gastos!$F$3:$F$502;Gastos!$B$3:$B$502;$A10;Gastos!$A$3:$A$502;">="&DATA(Configurações!$B$3;2;1);Gastos!$A$3:$A$502;"<="&FIM.MÊS(DATA(Configurações!$B$3;2;1))) | D10: =SOMASES(Gastos!$F$3:$F$502;Gastos!$B$3:$B$502;$A10;Gastos!$A$3:$A$502;">="&DATA(Configurações!$B$3;3;1);Gastos!$A$3:$A$502;"<="&FIM.MÊS(DATA(Configurações!$B$3;3;1))) | E10: =SOMASES(Gastos!$F$3:$F$502;Gastos!$B$3:$B$502;$A10;Gastos!$A$3:$A$502;">="&DATA(Configurações!$B$3;4;1);Gastos!$A$3:$A$502;"<="&FIM.MÊS(DATA(Configurações!$B$3;4;1))) | F10: =SOMASES(Gastos!$F$3:$F$502;Gastos!$B$3:$B$502;$A10;Gastos!$A$3:$A$502;">="&DATA(Configurações!$B$3;5;1);Gastos!$A$3:$A$502;"<="&FIM.MÊS(DATA(Configurações!$B$3;5;1))) | G10: =SOMASES(Gastos!$F$3:$F$502;Gastos!$B$3:$B$502;$A10;Gastos!$A$3:$A$502;">="&DATA(Configurações!$B$3;6;1);Gastos!$A$3:$A$502;"<="&FIM.MÊS(DATA(Configurações!$B$3;6;1))) | H10: =SOMASES(Gastos!$F$3:$F$502;Gastos!$B$3:$B$502;$A10;Gastos!$A$3:$A$502;">="&DATA(Configurações!$B$3;7;1);Gastos!$A$3:$A$502;"<="&FIM.MÊS(DATA(Configurações!$B$3;7;1))) | I10: =SOMASES(Gastos!$F$3:$F$502;Gastos!$B$3:$B$502;$A10;Gastos!$A$3:$A$502;">="&DATA(Configurações!$B$3;8;1);Gastos!$A$3:$A$502;"<="&FIM.MÊS(DATA(Configurações!$B$3;8;1))) | J10: =SOMASES(Gastos!$F$3:$F$502;Gastos!$B$3:$B$502;$A10;Gastos!$A$3:$A$502;">="&DATA(Configurações!$B$3;9;1);Gastos!$A$3:$A$502;"<="&FIM.MÊS(DATA(Configurações!$B$3;9;1))) | K10: =SOMASES(Gastos!$F$3:$F$502;Gastos!$B$3:$B$502;$A10;Gastos!$A$3:$A$502;">="&DATA(Configurações!$B$3;10;1);Gastos!$A$3:$A$502;"<="&FIM.MÊS(DATA(Configurações!$B$3;10;1))) | L10: =SOMASES(Gastos!$F$3:$F$502;Gastos!$B$3:$B$502;$A10;Gastos!$A$3:$A$502;">="&DATA(Configurações!$B$3;11;1);Gastos!$A$3:$A$502;"<="&FIM.MÊS(DATA(Configurações!$B$3;11;1))) | M10: =SOMASES(Gastos!$F$3:$F$502;Gastos!$B$3:$B$502;$A10;Gastos!$A$3:$A$502;">="&DATA(Configurações!$B$3;12;1);Gastos!$A$3:$A$502;"<="&FIM.MÊS(DATA(Configurações!$B$3;12;1))) | N10: =SOMA(B10:M10) | O10: =SE(N$18=0;"";N10/N$18)
A11: Manutenção | B11: =SOMASES(Gastos!$F$3:$F$502;Gastos!$B$3:$B$502;$A11;Gastos!$A$3:$A$502;">="&DATA(Configurações!$B$3;1;1);Gastos!$A$3:$A$502;"<="&FIM.MÊS(DATA(Configurações!$B$3;1;1))) | C11: =SOMASES(Gastos!$F$3:$F$502;Gastos!$B$3:$B$502;$A11;Gastos!$A$3:$A$502;">="&DATA(Configurações!$B$3;2;1);Gastos!$A$3:$A$502;"<="&FIM.MÊS(DATA(Configurações!$B$3;2;1))) | D11: =SOMASES(Gastos!$F$3:$F$502;Gastos!$B$3:$B$502;$A11;Gastos!$A$3:$A$502;">="&DATA(Configurações!$B$3;3;1);Gastos!$A$3:$A$502;"<="&FIM.MÊS(DATA(Configurações!$B$3;3;1))) | E11: =SOMASES(Gastos!$F$3:$F$502;Gastos!$B$3:$B$502;$A11;Gastos!$A$3:$A$502;">="&DATA(Configurações!$B$3;4;1);Gastos!$A$3:$A$502;"<="&FIM.MÊS(DATA(Configurações!$B$3;4;1))) | F11: =SOMASES(Gastos!$F$3:$F$502;Gastos!$B$3:$B$502;$A11;Gastos!$A$3:$A$502;">="&DATA(Configurações!$B$3;5;1);Gastos!$A$3:$A$502;"<="&FIM.MÊS(DATA(Configurações!$B$3;5;1))) | G11: =SOMASES(Gastos!$F$3:$F$502;Gastos!$B$3:$B$502;$A11;Gastos!$A$3:$A$502;">="&DATA(Configurações!$B$3;6;1);Gastos!$A$3:$A$502;"<="&FIM.MÊS(DATA(Configurações!$B$3;6;1))) | H11: =SOMASES(Gastos!$F$3:$F$502;Gastos!$B$3:$B$502;$A11;Gastos!$A$3:$A$502;">="&DATA(Configurações!$B$3;7;1);Gastos!$A$3:$A$502;"<="&FIM.MÊS(DATA(Configurações!$B$3;7;1))) | I11: =SOMASES(Gastos!$F$3:$F$502;Gastos!$B$3:$B$502;$A11;Gastos!$A$3:$A$502;">="&DATA(Configurações!$B$3;8;1);Gastos!$A$3:$A$502;"<="&FIM.MÊS(DATA(Configurações!$B$3;8;1))) | J11: =SOMASES(Gastos!$F$3:$F$502;Gastos!$B$3:$B$502;$A11;Gastos!$A$3:$A$502;">="&DATA(Configurações!$B$3;9;1);Gastos!$A$3:$A$502;"<="&FIM.MÊS(DATA(Configurações!$B$3;9;1))) | K11: =SOMASES(Gastos!$F$3:$F$502;Gastos!$B$3:$B$502;$A11;Gastos!$A$3:$A$502;">="&DATA(Configurações!$B$3;10;1);Gastos!$A$3:$A$502;"<="&FIM.MÊS(DATA(Configurações!$B$3;10;1))) | L11: =SOMASES(Gastos!$F$3:$F$502;Gastos!$B$3:$B$502;$A11;Gastos!$A$3:$A$502;">="&DATA(Configurações!$B$3;11;1);Gastos!$A$3:$A$502;"<="&FIM.MÊS(DATA(Configurações!$B$3;11;1))) | M11: =SOMASES(Gastos!$F$3:$F$502;Gastos!$B$3:$B$502;$A11;Gastos!$A$3:$A$502;">="&DATA(Configurações!$B$3;12;1);Gastos!$A$3:$A$502;"<="&FIM.MÊS(DATA(Configurações!$B$3;12;1))) | N11: =SOMA(B11:M11) | O11: =SE(N$18=0;"";N11/N$18)
A12: Obras | B12: =SOMASES(Gastos!$F$3:$F$502;Gastos!$B$3:$B$502;$A12;Gastos!$A$3:$A$502;">="&DATA(Configurações!$B$3;1;1);Gastos!$A$3:$A$502;"<="&FIM.MÊS(DATA(Configurações!$B$3;1;1))) | C12: =SOMASES(Gastos!$F$3:$F$502;Gastos!$B$3:$B$502;$A12;Gastos!$A$3:$A$502;">="&DATA(Configurações!$B$3;2;1);Gastos!$A$3:$A$502;"<="&FIM.MÊS(DATA(Configurações!$B$3;2;1))) | D12: =SOMASES(Gastos!$F$3:$F$502;Gastos!$B$3:$B$502;$A12;Gastos!$A$3:$A$502;">="&DATA(Configurações!$B$3;3;1);Gastos!$A$3:$A$502;"<="&FIM.MÊS(DATA(Configurações!$B$3;3;1))) | E12: =SOMASES(Gastos!$F$3:$F$502;Gastos!$B$3:$B$502;$A12;Gastos!$A$3:$A$502;">="&DATA(Configurações!$B$3;4;1);Gastos!$A$3:$A$502;"<="&FIM.MÊS(DATA(Configurações!$B$3;4;1))) | F12: =SOMASES(Gastos!$F$3:$F$502;Gastos!$B$3:$B$502;$A12;Gastos!$A$3:$A$502;">="&DATA(Configurações!$B$3;5;1);Gastos!$A$3:$A$502;"<="&FIM.MÊS(DATA(Configurações!$B$3;5;1))) | G12: =SOMASES(Gastos!$F$3:$F$502;Gastos!$B$3:$B$502;$A12;Gastos!$A$3:$A$502;">="&DATA(Configurações!$B$3;6;1);Gastos!$A$3:$A$502;"<="&FIM.MÊS(DATA(Configurações!$B$3;6;1))) | H12: =SOMASES(Gastos!$F$3:$F$502;Gastos!$B$3:$B$502;$A12;Gastos!$A$3:$A$502;">="&DATA(Configurações!$B$3;7;1);Gastos!$A$3:$A$502;"<="&FIM.MÊS(DATA(Configurações!$B$3;7;1))) | I12: =SOMASES(Gastos!$F$3:$F$502;Gastos!$B$3:$B$502;$A12;Gastos!$A$3:$A$502;">="&DATA(Configurações!$B$3;8;1);Gastos!$A$3:$A$502;"<="&FIM.MÊS(DATA(Configurações!$B$3;8;1))) | J12: =SOMASES(Gastos!$F$3:$F$502;Gastos!$B$3:$B$502;$A12;Gastos!$A$3:$A$502;">="&DATA(Configurações!$B$3;9;1);Gastos!$A$3:$A$502;"<="&FIM.MÊS(DATA(Configurações!$B$3;9;1))) | K12: =SOMASES(Gastos!$F$3:$F$502;Gastos!$B$3:$B$502;$A12;Gastos!$A$3:$A$502;">="&DATA(Configurações!$B$3;10;1);Gastos!$A$3:$A$502;"<="&FIM.MÊS(DATA(Configurações!$B$3;10;1))) | L12: =SOMASES(Gastos!$F$3:$F$502;Gastos!$B$3:$B$502;$A12;Gastos!$A$3:$A$502;">="&DATA(Configurações!$B$3;11;1);Gastos!$A$3:$A$502;"<="&FIM.MÊS(DATA(Configurações!$B$3;11;1))) | M12: =SOMASES(Gastos!$F$3:$F$502;Gastos!$B$3:$B$502;$A12;Gastos!$A$3:$A$502;">="&DATA(Configurações!$B$3;12;1);Gastos!$A$3:$A$502;"<="&FIM.MÊS(DATA(Configurações!$B$3;12;1))) | N12: =SOMA(B12:M12) | O12: =SE(N$18=0;"";N12/N$18)
A13: Secretaria | B13: =SOMASES(Gastos!$F$3:$F$502;Gastos!$B$3:$B$502;$A13;Gastos!$A$3:$A$502;">="&DATA(Configurações!$B$3;1;1);Gastos!$A$3:$A$502;"<="&FIM.MÊS(DATA(Configurações!$B$3;1;1))) | C13: =SOMASES(Gastos!$F$3:$F$502;Gastos!$B$3:$B$502;$A13;Gastos!$A$3:$A$502;">="&DATA(Configurações!$B$3;2;1);Gastos!$A$3:$A$502;"<="&FIM.MÊS(DATA(Configurações!$B$3;2;1))) | D13: =SOMASES(Gastos!$F$3:$F$502;Gastos!$B$3:$B$502;$A13;Gastos!$A$3:$A$502;">="&DATA(Configurações!$B$3;3;1);Gastos!$A$3:$A$502;"<="&FIM.MÊS(DATA(Configurações!$B$3;3;1))) | E13: =SOMASES(Gastos!$F$3:$F$502;Gastos!$B$3:$B$502;$A13;Gastos!$A$3:$A$502;">="&DATA(Configurações!$B$3;4;1);Gastos!$A$3:$A$502;"<="&FIM.MÊS(DATA(Configurações!$B$3;4;1))) | F13: =SOMASES(Gastos!$F$3:$F$502;Gastos!$B$3:$B$502;$A13;Gastos!$A$3:$A$502;">="&DATA(Configurações!$B$3;5;1);Gastos!$A$3:$A$502;"<="&FIM.MÊS(DATA(Configurações!$B$3;5;1))) | G13: =SOMASES(Gastos!$F$3:$F$502;Gastos!$B$3:$B$502;$A13;Gastos!$A$3:$A$502;">="&DATA(Configurações!$B$3;6;1);Gastos!$A$3:$A$502;"<="&FIM.MÊS(DATA(Configurações!$B$3;6;1))) | H13: =SOMASES(Gastos!$F$3:$F$502;Gastos!$B$3:$B$502;$A13;Gastos!$A$3:$A$502;">="&DATA(Configurações!$B$3;7;1);Gastos!$A$3:$A$502;"<="&FIM.MÊS(DATA(Configurações!$B$3;7;1))) | I13: =SOMASES(Gastos!$F$3:$F$502;Gastos!$B$3:$B$502;$A13;Gastos!$A$3:$A$502;">="&DATA(Configurações!$B$3;8;1);Gastos!$A$3:$A$502;"<="&FIM.MÊS(DATA(Configurações!$B$3;8;1))) | J13: =SOMASES(Gastos!$F$3:$F$502;Gastos!$B$3:$B$502;$A13;Gastos!$A$3:$A$502;">="&DATA(Configurações!$B$3;9;1);Gastos!$A$3:$A$502;"<="&FIM.MÊS(DATA(Configurações!$B$3;9;1))) | K13: =SOMASES(Gastos!$F$3:$F$502;Gastos!$B$3:$B$502;$A13;Gastos!$A$3:$A$502;">="&DATA(Configurações!$B$3;10;1);Gastos!$A$3:$A$502;"<="&FIM.MÊS(DATA(Configurações!$B$3;10;1))) | L13: =SOMASES(Gastos!$F$3:$F$502;Gastos!$B$3:$B$502;$A13;Gastos!$A$3:$A$502;">="&DATA(Configurações!$B$3;11;1);Gastos!$A$3:$A$502;"<="&FIM.MÊS(DATA(Configurações!$B$3;11;1))) | M13: =SOMASES(Gastos!$F$3:$F$502;Gastos!$B$3:$B$502;$A13;Gastos!$A$3:$A$502;">="&DATA(Configurações!$B$3;12;1);Gastos!$A$3:$A$502;"<="&FIM.MÊS(DATA(Configurações!$B$3;12;1))) | N13: =SOMA(B13:M13) | O13: =SE(N$18=0;"";N13/N$18)
A14: Eventos | B14: =SOMASES(Gastos!$F$3:$F$502;Gastos!$B$3:$B$502;$A14;Gastos!$A$3:$A$502;">="&DATA(Configurações!$B$3;1;1);Gastos!$A$3:$A$502;"<="&FIM.MÊS(DATA(Configurações!$B$3;1;1))) | C14: =SOMASES(Gastos!$F$3:$F$502;Gastos!$B$3:$B$502;$A14;Gastos!$A$3:$A$502;">="&DATA(Configurações!$B$3;2;1);Gastos!$A$3:$A$502;"<="&FIM.MÊS(DATA(Configurações!$B$3;2;1))) | D14: =SOMASES(Gastos!$F$3:$F$502;Gastos!$B$3:$B$502;$A14;Gastos!$A$3:$A$502;">="&DATA(Configurações!$B$3;3;1);Gastos!$A$3:$A$502;"<="&FIM.MÊS(DATA(Configurações!$B$3;3;1))) | E14: =SOMASES(Gastos!$F$3:$F$502;Gastos!$B$3:$B$502;$A14;Gastos!$A$3:$A$502;">="&DATA(Configurações!$B$3;4;1);Gastos!$A$3:$A$502;"<="&FIM.MÊS(DATA(Configurações!$B$3;4;1))) | F14: =SOMASES(Gastos!$F$3:$F$502;Gastos!$B$3:$B$502;$A14;Gastos!$A$3:$A$502;">="&DATA(Configurações!$B$3;5;1);Gastos!$A$3:$A$502;"<="&FIM.MÊS(DATA(Configurações!$B$3;5;1))) | G14: =SOMASES(Gastos!$F$3:$F$502;Gastos!$B$3:$B$502;$A14;Gastos!$A$3:$A$502;">="&DATA(Configurações!$B$3;6;1);Gastos!$A$3:$A$502;"<="&FIM.MÊS(DATA(Configurações!$B$3;6;1))) | H14: =SOMASES(Gastos!$F$3:$F$502;Gastos!$B$3:$B$502;$A14;Gastos!$A$3:$A$502;">="&DATA(Configurações!$B$3;7;1);Gastos!$A$3:$A$502;"<="&FIM.MÊS(DATA(Configurações!$B$3;7;1))) | I14: =SOMASES(Gastos!$F$3:$F$502;Gastos!$B$3:$B$502;$A14;Gastos!$A$3:$A$502;">="&DATA(Configurações!$B$3;8;1);Gastos!$A$3:$A$502;"<="&FIM.MÊS(DATA(Configurações!$B$3;8;1))) | J14: =SOMASES(Gastos!$F$3:$F$502;Gastos!$B$3:$B$502;$A14;Gastos!$A$3:$A$502;">="&DATA(Configurações!$B$3;9;1);Gastos!$A$3:$A$502;"<="&FIM.MÊS(DATA(Configurações!$B$3;9;1))) | K14: =SOMASES(Gastos!$F$3:$F$502;Gastos!$B$3:$B$502;$A14;Gastos!$A$3:$A$502;">="&DATA(Configurações!$B$3;10;1);Gastos!$A$3:$A$502;"<="&FIM.MÊS(DATA(Configurações!$B$3;10;1))) | L14: =SOMASES(Gastos!$F$3:$F$502;Gastos!$B$3:$B$502;$A14;Gastos!$A$3:$A$502;">="&DATA(Configurações!$B$3;11;1);Gastos!$A$3:$A$502;"<="&FIM.MÊS(DATA(Configurações!$B$3;11;1))) | M14: =SOMASES(Gastos!$F$3:$F$502;Gastos!$B$3:$B$502;$A14;Gastos!$A$3:$A$502;">="&DATA(Configurações!$B$3;12;1);Gastos!$A$3:$A$502;"<="&FIM.MÊS(DATA(Configurações!$B$3;12;1))) | N14: =SOMA(B14:M14) | O14: =SE(N$18=0;"";N14/N$18)
... A17: Outros | B17: =SOMASES(Gastos!$F$3:$F$502;Gastos!$B$3:$B$502;$A17;Gastos!$A$3:$A$502;">="&DATA(Configurações!$B$3;1;1);Gastos!$A$3:$A$502;"<="&FIM.MÊS(DATA(Configurações!$B$3;1;1))) | C17: =SOMASES(Gastos!$F$3:$F$502;Gastos!$B$3:$B$502;$A17;Gastos!$A$3:$A$502;">="&DATA(Configurações!$B$3;2;1);Gastos!$A$3:$A$502;"<="&FIM.MÊS(DATA(Configurações!$B$3;2;1))) | D17: =SOMASES(Gastos!$F$3:$F$502;Gastos!$B$3:$B$502;$A17;Gastos!$A$3:$A$502;">="&DATA(Configurações!$B$3;3;1);Gastos!$A$3:$A$502;"<="&FIM.MÊS(DATA(Configurações!$B$3;3;1))) | E17: =SOMASES(Gastos!$F$3:$F$502;Gastos!$B$3:$B$502;$A17;Gastos!$A$3:$A$502;">="&DATA(Configurações!$B$3;4;1);Gastos!$A$3:$A$502;"<="&FIM.MÊS(DATA(Configurações!$B$3;4;1))) | F17: =SOMASES(Gastos!$F$3:$F$502;Gastos!$B$3:$B$502;$A17;Gastos!$A$3:$A$502;">="&DATA(Configurações!$B$3;5;1);Gastos!$A$3:$A$502;"<="&FIM.MÊS(DATA(Configurações!$B$3;5;1))) | G17: =SOMASES(Gastos!$F$3:$F$502;Gastos!$B$3:$B$502;$A17;Gastos!$A$3:$A$502;">="&DATA(Configurações!$B$3;6;1);Gastos!$A$3:$A$502;"<="&FIM.MÊS(DATA(Configurações!$B$3;6;1))) | H17: =SOMASES(Gastos!$F$3:$F$502;Gastos!$B$3:$B$502;$A17;Gastos!$A$3:$A$502;">="&DATA(Configurações!$B$3;7;1);Gastos!$A$3:$A$502;"<="&FIM.MÊS(DATA(Configurações!$B$3;7;1))) | I17: =SOMASES(Gastos!$F$3:$F$502;Gastos!$B$3:$B$502;$A17;Gastos!$A$3:$A$502;">="&DATA(Configurações!$B$3;8;1);Gastos!$A$3:$A$502;"<="&FIM.MÊS(DATA(Configurações!$B$3;8;1))) | J17: =SOMASES(Gastos!$F$3:$F$502;Gastos!$B$3:$B$502;$A17;Gastos!$A$3:$A$502;">="&DATA(Configurações!$B$3;9;1);Gastos!$A$3:$A$502;"<="&FIM.MÊS(DATA(Configurações!$B$3;9;1))) | K17: =SOMASES(Gastos!$F$3:$F$502;Gastos!$B$3:$B$502;$A17;Gastos!$A$3:$A$502;">="&DATA(Configurações!$B$3;10;1);Gastos!$A$3:$A$502;"<="&FIM.MÊS(DATA(Configurações!$B$3;10;1))) | L17: =SOMASES(Gastos!$F$3:$F$502;Gastos!$B$3:$B$502;$A17;Gastos!$A$3:$A$502;">="&DATA(Configurações!$B$3;11;1);Gastos!$A$3:$A$502;"<="&FIM.MÊS(DATA(Configurações!$B$3;11;1))) | M17: =SOMASES(Gastos!$F$3:$F$502;Gastos!$B$3:$B$502;$A17;Gastos!$A$3:$A$502;">="&DATA(Configurações!$B$3;12;1);Gastos!$A$3:$A$502;"<="&FIM.MÊS(DATA(Configurações!$B$3;12;1))) | N17: =SOMA(B17:M17) | O17: =SE(N$18=0;"";N17/N$18)
A18: TOTAL | B18: =SOMA(B3:B17) | C18: =SOMA(C3:C17) | D18: =SOMA(D3:D17) | E18: =SOMA(E3:E17) | F18: =SOMA(F3:F17) | G18: =SOMA(G3:G17) | H18: =SOMA(H3:H17) | I18: =SOMA(I3:I17) | ... N18: =SOMA(N3:N17)

Sheet Comparativo Anual
A1: 📈 Comparativo entre Anos
A2: Indicador | B2: 2024 | C2: 2025 | D2: 2026 | E2: Variação %
A3: Dízimos | B3: 0 | C3: 0 | D3: ='Resumo Financeiro'!B15 | E3: =SE(C3=0;"";(D3-C3)/ABS(C3))
A4: Doações | B4: 0 | C4: 0 | D4: ='Resumo Financeiro'!C15 | E4: =SE(C4=0;"";(D4-C4)/ABS(C4))
A5: Missas | B5: 0 | C5: 0 | D5: ='Resumo Financeiro'!D15 | E5: =SE(C5=0;"";(D5-C5)/ABS(C5))
A6: Total Entradas | B6: 0 | C6: 0 | D6: ='Resumo Financeiro'!E15 | E6: =SE(C6=0;"";(D6-C6)/ABS(C6))
A7: Total Gastos | B7: 0 | C7: 0 | D7: ='Resumo Financeiro'!F15 | E7: =SE(C7=0;"";(D7-C7)/ABS(C7))
A8: Resultado | B8: 0 | C8: 0 | D8: ='Resumo Financeiro'!G15 | E8: =SE(C8=0;"";(D8-C8)/ABS(C8))
A11: ℹ️ Preencha manualmente os anos anteriores. O ano atual é calculado automaticamente.

Sheet Plano de Contas
A1: 📋 Plano de Contas
A3: RECEITAS | D3: DESPESAS
A5: R01 | B5: Dízimos | D5: D01 | E5: Água
A6: R02 | B6: Doações | D6: D02 | E6: Energia
A7: R03 | B7: Missas | D7: D03 | E7: Internet
A8: R04 | B8: Campanhas | D8: D04 | E8: Limpeza
A9: R05 | B9: Festas | D9: D05 | E9: Material Litúrgico
A10: R06 | B10: Eventos | D10: D06 | E10: Flores
A11: R07 | B11: Rifas | D11: D07 | E11: Manutenção
A12: R08 | B12: Outros | D12: D08 | E12: Construção
D13: D09 | E13: Equipamentos
D14: D10 | E14: Secretaria
D15: D11 | E15: Eventos
D16: D12 | E16: Transporte
D17: D13 | E17: Outros

Sheet Fluxo de Caixa
A1: 💵 Fluxo de Caixa
A2: Data | B2: Descrição | C2: Entrada | D2: Saída | E2: Saldo
B3: Saldo Inicial (Caixa + Banco) | E3: =Configurações!$B$10
A4: =_Consolidado!A2 | B4: =_Consolidado!B2 | C4: =_Consolidado!C2 | D4: =_Consolidado!D2 | E4: =SE(A4="";E3;E3+SEERRO(C4;0)-SEERRO(D4;0))
A5: =_Consolidado!A3 | B5: =_Consolidado!B3 | C5: =_Consolidado!C3 | D5: =_Consolidado!D3 | E5: =SE(A5="";E4;E4+SEERRO(C5;0)-SEERRO(D5;0))
A6: =_Consolidado!A4 | B6: =_Consolidado!B4 | C6: =_Consolidado!C4 | D6: =_Consolidado!D4 | E6: =SE(A6="";E5;E5+SEERRO(C6;0)-SEERRO(D6;0))
A7: =_Consolidado!A5 | B7: =_Consolidado!B5 | C7: =_Consolidado!C5 | D7: =_Consolidado!D5 | E7: =SE(A7="";E6;E6+SEERRO(C7;0)-SEERRO(D7;0))
A8: =_Consolidado!A6 | B8: =_Consolidado!B6 | C8: =_Consolidado!C6 | D8: =_Consolidado!D6 | E8: =SE(A8="";E7;E7+SEERRO(C8;0)-SEERRO(D8;0))
A9: =_Consolidado!A7 | B9: =_Consolidado!B7 | C9: =_Consolidado!C7 | D9: =_Consolidado!D7 | E9: =SE(A9="";E8;E8+SEERRO(C9;0)-SEERRO(D9;0))
A10: =_Consolidado!A8 | B10: =_Consolidado!B8 | C10: =_Consolidado!C8 | D10: =_Consolidado!D8 | E10: =SE(A10="";E9;E9+SEERRO(C10;0)-SEERRO(D10;0))
A11: =_Consolidado!A9 | B11: =_Consolidado!B9 | C11: =_Consolidado!C9 | D11: =_Consolidado!D9 | E11: =SE(A11="";E10;E10+SEERRO(C11;0)-SEERRO(D11;0))
A12: =_Consolidado!A10 | B12: =_Consolidado!B10 | C12: =_Consolidado!C10 | D12: =_Consolidado!D10 | E12: =SE(A12="";E11;E11+SEERRO(C12;0)-SEERRO(D12;0))
A13: =_Consolidado!A11 | B13: =_Consolidado!B11 | C13: =_Consolidado!C11 | D13: =_Consolidado!D11 | E13: =SE(A13="";E12;E12+SEERRO(C13;0)-SEERRO(D13;0))
A14: =_Consolidado!A12 | B14: =_Consolidado!B12 | C14: =_Consolidado!C12 | D14: =_Consolidado!D12 | E14: =SE(A14="";E13;E13+SEERRO(C14;0)-SEERRO(D14;0))
A15: =_Consolidado!A13 | B15: =_Consolidado!B13 | C15: =_Consolidado!C13 | D15: =_Consolidado!D13 | E15: =SE(A15="";E14;E14+SEERRO(C15;0)-SEERRO(D15;0))
... A503: =_Consolidado!A501 | B503: =_Consolidado!B501 | C503: =_Consolidado!C501 | D503: =_Consolidado!D501 | E503: =SE(A503="";E502;E502+SEERRO(C503;0)-SEERRO(D503;0))

Sheet Impressão A4
A1: 🖨️ Relatórios para Impressão (A4)
A3: Selecione o mês para relatórios mensais: | B3: Janeiro
A5: =Configurações!$B$4
A6: PRESTAÇÃO DE CONTAS MENSAL
A7: Período: | B7: =B3&" / "&Configurações!$B$3 | D7: Emissão: | E7: =HOJE()
A9: Item | B9: Valor
A10: Dízimos | B10: =ÍNDICE('Resumo Financeiro'!B3:B14;CORRESP(B3;'Resumo Financeiro'!A3:A14;0))
A11: Doações | B11: =ÍNDICE('Resumo Financeiro'!C3:C14;CORRESP(B3;'Resumo Financeiro'!A3:A14;0))
A12: Missas | B12: =ÍNDICE('Resumo Financeiro'!D3:D14;CORRESP(B3;'Resumo Financeiro'!A3:A14;0))
A13: Total Entradas | B13: =ÍNDICE('Resumo Financeiro'!E3:E14;CORRESP(B3;'Resumo Financeiro'!A3:A14;0))
A14: Gastos | B14: =ÍNDICE('Resumo Financeiro'!F3:F14;CORRESP(B3;'Resumo Financeiro'!A3:A14;0))
A15: Saldo do Mês | B15: =ÍNDICE('Resumo Financeiro'!G3:G14;CORRESP(B3;'Resumo Financeiro'!A3:A14;0))
A18: ______________________________ | D18: ______________________________
A19: Tesoureiro(a) | D19: Pároco / Presidente
A45: =Configurações!$B$4
A46: PRESTAÇÃO DE CONTAS ANUAL
A47: Período: | B47: =Configurações!$B$3 | D47: Emissão: | E47: =HOJE()
A50: Total Receitas | B50: ='Resumo Financeiro'!E15
A51: Total Despesas | B51: ='Resumo Financeiro'!F15
A52: Resultado | B52: ='Resumo Financeiro'!G15
A53: Saldo Final | B53: =Configurações!$B$10+'Resumo Financeiro'!G15
A56: ______________________________ | D56: ______________________________
A57: Tesoureiro(a) | D57: Pároco / Presidente
A85: =Configurações!$B$4
A86: RESUMO FINANCEIRO
A87: Período: | B87: =B3 | D87: Emissão: | E87: =HOJE()
A89: Consulte as abas Relatório Anual e Relatório Despesas para detalhes.
A92: ______________________________ | D92: ______________________________
A93: Tesoureiro(a) | D93: Pároco / Presidente
A120: =Configurações!$B$4
A121: DEMONSTRATIVO DE RECEITAS E DESPESAS
A122: Período: | B122: =Configurações!$B$3 | D122: Emissão: | E122: =HOJE()
A124: Consulte as abas Relatório Anual e Relatório Despesas para detalhes.
A127: ______________________________ | D127: ______________________________
A128: Tesoureiro(a) | D128: Pároco / Presidente

Sheet Configurações
A1: ⚙️ Configurações — Parâmetros e Listas
A3: Ano de Referência | B3: 2026
A4: Nome da Igreja | B4: Paróquia / Comunidade
A6: 💰 SALDO INICIAL (antes dos lançamentos do ano)
A7: Conta | B7: Saldo Inicial
A8: Caixa | B8: 0
A9: Banco | B9: 0
A10: Total | B10: =SOMA(B8:B9)
A12: 🎯 METAS MENSAIS DE ARRECADAÇÃO
B13: Jan | C13: Fev | D13: Mar | E13: Abr | F13: Mai | G13: Jun | H13: Jul | I13: Ago | J13: Set | K13: Out | L13: Nov | M13: Dez
B14: 0 | C14: 0 | D14: 0 | E14: 0 | F14: 0 | G14: 0 | H14: 0 | I14: 0 | J14: 0 | K14: 0 | L14: 0 | M14: 0
A16: ⚠️ LIMITES MENSAIS DE GASTOS POR CATEGORIA
A34: 📅 Meses (filtros e listas) | B34: Ano Inteiro
B35: Janeiro | D35: Formas de Pagamento | G35: Responsáveis | J35: Contas
B36: Fevereiro | E36: Dinheiro | H36: Tesoureiro(a) | J36: Caixa
B37: Março | E37: PIX | H37: Pároco | J37: Banco
B38: Abril | E38: Transferência | H38: Secretário(a)
B39: Maio | E39: Cartão Débito | H39: Vice-Tesoureiro(a)
B40: Junho | E40: Cartão Crédito | H40: Outro
B41: Julho | E41: Cheque
B42: Agosto | E42: Depósito
B43: Setembro
B44: Outubro
B45: Novembro
B46: Dezembro
A50: Tipos de Receitas | D50: Tipos de Despesas | H50: Categoria | I50: Limite Mensal
B51: Dízimos | E51: Água | H51: Água | I51: 0
B52: Doações | E52: Energia | H52: Energia | I52: 0
B53: Missas | E53: Internet | H53: Limpeza | I53: 0
B54: Campanhas | E54: Limpeza | H54: Material Litúrgico | I54: 0
B55: Festas | E55: Material Litúrgico | H55: Hóstias | I55: 0
B56: Eventos | E56: Flores | H56: Vinho | I56: 0
B57: Rifas | E57: Manutenção | H57: Flores | I57: 0
B58: Outros | E58: Construção | H58: Som | I58: 0
E59: Equipamentos | H59: Manutenção | I59: 0
E60: Secretaria | H60: Obras | I60: 0
E61: Eventos | H61: Secretaria | I61: 0
E62: Transporte | H62: Eventos | I62: 0
E63: Outros | H63: Alimentação | I63: 0
H64: Transporte | I64: 0
...

Sheet Novo Exercício
A1: 🔄 Iniciar Novo Exercício Financeiro
A3: ▶ NOVO EXERCÍCIO
A5: Este botão/macro executa automaticamente:
A6: • Limpa lançamentos do ano anterior (Dízimos, Doações, Missas, Gastos, Conciliação)
A7: • Mantém fórmulas, gráficos, Dashboard e configurações de listas
A8: • Incrementa o ano (ex: 2026 → 2027)
A9: • Preenche domingos do novo ano na aba Missas
A10: • Arquiva totais do ano no Comparativo Anual
A12: COMO ATIVAR O BOTÃO:
A13: 1. Salve a planilha como .xlsm (Excel com macros)
A14: 2. Pressione Alt+F11 → Arquivo → Importar → vba/NovoExercicio.bas
A15: 3. Desenvolvedor → Inserir → Botão → associe à macro NovoExercicio
... A18: python gerar_planilha.py --novo-exercicio

Sheet _Consolidado
A2: =SE('Dízimos Mensais'!A3="";"";'Dízimos Mensais'!A3) | B2: =SE('Dízimos Mensais'!A3="";"";"Dízimo - "&'Dízimos Mensais'!B3) | C2: =SE('Dízimos Mensais'!A3="";"";'Dízimos Mensais'!E3) | D2: =SE('Dízimos Mensais'!A3="";"";0)
A3: =SE('Dízimos Mensais'!A4="";"";'Dízimos Mensais'!A4) | B3: =SE('Dízimos Mensais'!A4="";"";"Dízimo - "&'Dízimos Mensais'!B4) | C3: =SE('Dízimos Mensais'!A4="";"";'Dízimos Mensais'!E4) | D3: =SE('Dízimos Mensais'!A4="";"";0)
A4: =SE('Dízimos Mensais'!A5="";"";'Dízimos Mensais'!A5) | B4: =SE('Dízimos Mensais'!A5="";"";"Dízimo - "&'Dízimos Mensais'!B5) | C4: =SE('Dízimos Mensais'!A5="";"";'Dízimos Mensais'!E5) | D4: =SE('Dízimos Mensais'!A5="";"";0)
A5: =SE('Dízimos Mensais'!A6="";"";'Dízimos Mensais'!A6) | B5: =SE('Dízimos Mensais'!A6="";"";"Dízimo - "&'Dízimos Mensais'!B6) | C5: =SE('Dízimos Mensais'!A6="";"";'Dízimos Mensais'!E6) | D5: =SE('Dízimos Mensais'!A6="";"";0)
A6: =SE('Dízimos Mensais'!A7="";"";'Dízimos Mensais'!A7) | B6: =SE('Dízimos Mensais'!A7="";"";"Dízimo - "&'Dízimos Mensais'!B7) | C6: =SE('Dízimos Mensais'!A7="";"";'Dízimos Mensais'!E7) | D6: =SE('Dízimos Mensais'!A7="";"";0)
A7: =SE('Dízimos Mensais'!A8="";"";'Dízimos Mensais'!A8) | B7: =SE('Dízimos Mensais'!A8="";"";"Dízimo - "&'Dízimos Mensais'!B8) | C7: =SE('Dízimos Mensais'!A8="";"";'Dízimos Mensais'!E8) | D7: =SE('Dízimos Mensais'!A8="";"";0)
A8: =SE('Dízimos Mensais'!A9="";"";'Dízimos Mensais'!A9) | B8: =SE('Dízimos Mensais'!A9="";"";"Dízimo - "&'Dízimos Mensais'!B9) | C8: =SE('Dízimos Mensais'!A9="";"";'Dízimos Mensais'!E9) | D8: =SE('Dízimos Mensais'!A9="";"";0)
A9: =SE('Dízimos Mensais'!A10="";"";'Dízimos Mensais'!A10) | B9: =SE('Dízimos Mensais'!A10="";"";"Dízimo - "&'Dízimos Mensais'!B10) | C9: =SE('Dízimos Mensais'!A10="";"";'Dízimos Mensais'!E10) | D9: =SE('Dízimos Mensais'!A10="";"";0)
A10: =SE('Dízimos Mensais'!A11="";"";'Dízimos Mensais'!A11) | B10: =SE('Dízimos Mensais'!A11="";"";"Dízimo - "&'Dízimos Mensais'!B11) | C10: =SE('Dízimos Mensais'!A11="";"";'Dízimos Mensais'!E11) | D10: =SE('Dízimos Mensais'!A11="";"";0)
